2022-09-17 17:05:00,676 INFO: Microblog startup [in /Users/henryspivey/Desktop/Python/Python_Projects/microblog/app/__init__.py:57]
2022-09-17 17:05:04,222 ERROR: Exception on /edit_profile [POST] [in /Users/henryspivey/Desktop/Python/Python_Projects/microblog/venv/lib/python3.9/site-packages/flask/app.py:1449]
Traceback (most recent call last):
  File "/Users/henryspivey/Desktop/Python/Python_Projects/microblog/venv/lib/python3.9/site-packages/sqlalchemy/engine/base.py", line 1819, in _execute_context
    self.dialect.do_execute(
  File "/Users/henryspivey/Desktop/Python/Python_Projects/microblog/venv/lib/python3.9/site-packages/sqlalchemy/engine/default.py", line 732, in do_execute
    cursor.execute(statement, parameters)
sqlite3.IntegrityError: UNIQUE constraint failed: user.username

The above exception was the direct cause of the following exception:

Traceback (most recent call last):
  File "/Users/henryspivey/Desktop/Python/Python_Projects/microblog/venv/lib/python3.9/site-packages/flask/app.py", line 2073, in wsgi_app
    response = self.full_dispatch_request()
  File "/Users/henryspivey/Desktop/Python/Python_Projects/microblog/venv/lib/python3.9/site-packages/flask/app.py", line 1519, in full_dispatch_request
    rv = self.handle_user_exception(e)
  File "/Users/henryspivey/Desktop/Python/Python_Projects/microblog/venv/lib/python3.9/site-packages/flask/app.py", line 1517, in full_dispatch_request
    rv = self.dispatch_request()
  File "/Users/henryspivey/Desktop/Python/Python_Projects/microblog/venv/lib/python3.9/site-packages/flask/app.py", line 1503, in dispatch_request
    return self.ensure_sync(self.view_functions[rule.endpoint])(**req.view_args)
  File "/Users/henryspivey/Desktop/Python/Python_Projects/microblog/venv/lib/python3.9/site-packages/flask_login/utils.py", line 290, in decorated_view
    return current_app.ensure_sync(func)(*args, **kwargs)
  File "/Users/henryspivey/Desktop/Python/Python_Projects/microblog/app/routes.py", line 91, in edit_profile
    db.session.commit()
  File "<string>", line 2, in commit
  File "/Users/henryspivey/Desktop/Python/Python_Projects/microblog/venv/lib/python3.9/site-packages/sqlalchemy/orm/session.py", line 1451, in commit
    self._transaction.commit(_to_root=self.future)
  File "/Users/henryspivey/Desktop/Python/Python_Projects/microblog/venv/lib/python3.9/site-packages/sqlalchemy/orm/session.py", line 829, in commit
    self._prepare_impl()
  File "/Users/henryspivey/Desktop/Python/Python_Projects/microblog/venv/lib/python3.9/site-packages/sqlalchemy/orm/session.py", line 808, in _prepare_impl
    self.session.flush()
  File "/Users/henryspivey/Desktop/Python/Python_Projects/microblog/venv/lib/python3.9/site-packages/sqlalchemy/orm/session.py", line 3383, in flush
    self._flush(objects)
  File "/Users/henryspivey/Desktop/Python/Python_Projects/microblog/venv/lib/python3.9/site-packages/sqlalchemy/orm/session.py", line 3523, in _flush
    transaction.rollback(_capture_exception=True)
  File "/Users/henryspivey/Desktop/Python/Python_Projects/microblog/venv/lib/python3.9/site-packages/sqlalchemy/util/langhelpers.py", line 70, in __exit__
    compat.raise_(
  File "/Users/henryspivey/Desktop/Python/Python_Projects/microblog/venv/lib/python3.9/site-packages/sqlalchemy/util/compat.py", line 208, in raise_
    raise exception
  File "/Users/henryspivey/Desktop/Python/Python_Projects/microblog/venv/lib/python3.9/site-packages/sqlalchemy/orm/session.py", line 3483, in _flush
    flush_context.execute()
  File "/Users/henryspivey/Desktop/Python/Python_Projects/microblog/venv/lib/python3.9/site-packages/sqlalchemy/orm/unitofwork.py", line 456, in execute
    rec.execute(self)
  File "/Users/henryspivey/Desktop/Python/Python_Projects/microblog/venv/lib/python3.9/site-packages/sqlalchemy/orm/unitofwork.py", line 630, in execute
    util.preloaded.orm_persistence.save_obj(
  File "/Users/henryspivey/Desktop/Python/Python_Projects/microblog/venv/lib/python3.9/site-packages/sqlalchemy/orm/persistence.py", line 237, in save_obj
    _emit_update_statements(
  File "/Users/henryspivey/Desktop/Python/Python_Projects/microblog/venv/lib/python3.9/site-packages/sqlalchemy/orm/persistence.py", line 1001, in _emit_update_statements
    c = connection._execute_20(
  File "/Users/henryspivey/Desktop/Python/Python_Projects/microblog/venv/lib/python3.9/site-packages/sqlalchemy/engine/base.py", line 1631, in _execute_20
    return meth(self, args_10style, kwargs_10style, execution_options)
  File "/Users/henryspivey/Desktop/Python/Python_Projects/microblog/venv/lib/python3.9/site-packages/sqlalchemy/sql/elements.py", line 332, in _execute_on_connection
    return connection._execute_clauseelement(
  File "/Users/henryspivey/Desktop/Python/Python_Projects/microblog/venv/lib/python3.9/site-packages/sqlalchemy/engine/base.py", line 1498, in _execute_clauseelement
    ret = self._execute_context(
  File "/Users/henryspivey/Desktop/Python/Python_Projects/microblog/venv/lib/python3.9/site-packages/sqlalchemy/engine/base.py", line 1862, in _execute_context
    self._handle_dbapi_exception(
  File "/Users/henryspivey/Desktop/Python/Python_Projects/microblog/venv/lib/python3.9/site-packages/sqlalchemy/engine/base.py", line 2043, in _handle_dbapi_exception
    util.raise_(
  File "/Users/henryspivey/Desktop/Python/Python_Projects/microblog/venv/lib/python3.9/site-packages/sqlalchemy/util/compat.py", line 208, in raise_
    raise exception
  File "/Users/henryspivey/Desktop/Python/Python_Projects/microblog/venv/lib/python3.9/site-packages/sqlalchemy/engine/base.py", line 1819, in _execute_context
    self.dialect.do_execute(
  File "/Users/henryspivey/Desktop/Python/Python_Projects/microblog/venv/lib/python3.9/site-packages/sqlalchemy/engine/default.py", line 732, in do_execute
    cursor.execute(statement, parameters)
sqlalchemy.exc.IntegrityError: (sqlite3.IntegrityError) UNIQUE constraint failed: user.username
[SQL: UPDATE user SET username=?, about_me=? WHERE user.id = ?]
[parameters: ('henry', 'Lorem ipsumasdfasdf', 2)]
(Background on this error at: https://sqlalche.me/e/14/gkpj)
